<?xml version="1.0" encoding="utf-8"?>
<!-- =================================================================================== -->
<!-- |    This document was autogenerated by xacro from anymal.urdf.xacro              | -->
<!-- |    EDITING THIS FILE BY HAND IS NOT RECOMMENDED                                 | -->
<!-- =================================================================================== -->
<!-- This file contains the description of the ANYmal Boxy robot. -->
<robot name="anymal" xmlns:xacro="http://www.ros.org/wiki/xacro">
    <material name="black">
        <color rgba="0.0 0.0 0.0 1.0"/>
    </material>
    <material name="blue">
        <color rgba="0.0 0.0 0.8 1.0"/>
    </material>
    <material name="green">
        <color rgba="0.0 0.8 0.0 1.0"/>
    </material>
    <material name="grey">
        <color rgba="0.2 0.2 0.2 1.0"/>
    </material>
    <material name="light_grey">
        <color rgba="0.4 0.4 0.4 1.0"/>
    </material>
    <material name="orange">
        <color rgba="1.0 0.423529411765 0.0392156862745 1.0"/>
    </material>
    <material name="brown">
        <color rgba="0.870588235294 0.811764705882 0.764705882353 1.0"/>
    </material>
    <material name="red">
        <color rgba="0.8 0.0 0.0 1.0"/>
    </material>
    <material name="white">
        <color rgba="1.0 1.0 1.0 1.0"/>
    </material>
    <!-- Material for the visual primitives -->
    <material name="anymal_material">
        <color rgba="0.7 0.7 0.7 1.0"/>
    </material>
    <!-- Xacro:Properties -->
    <!-- [m] -->
    <!-- Base link -->
    <link name="base">
        <collision>
            <!-- Main Body -->
            <origin rpy="0 0 0" xyz="0 0 0.08"/>
            <geometry>
                <box size="0.531 0.27 0.24"/>
            </geometry>
        </collision>
        <collision>
            <!-- Belly plate front bump -->
            <origin rpy="0 0 0" xyz="0.2155 0.0 -0.09"/>
            <geometry>
                <box size="0.1 0.1 0.07"/>
            </geometry>
        </collision>
        <collision>
            <!-- Belly plate hind bump-->
            <origin rpy="0 0 0" xyz="-0.2155 0.0 -0.09"/>
            <geometry>
                <box size="0.1 0.1 0.07"/>
            </geometry>
        </collision>
    </link>
    <!-- Fixed joint to add dummy inertia link -->
    <joint name="base_to_base_inertia" type="fixed">
        <parent link="base"/>
        <child link="base_inertia"/>
        <origin rpy="0 0 0" xyz="0 0 0"/>
    </joint>
    <!-- Dummy inertia link, because KDL cannot have inertia on the base link -->
    <link name="base_inertia">
        <inertial>
            <origin rpy="0 0 0" xyz="-0.001960558279 -0.001413217745 0.050207125344"/>
            <mass value="16.793507758"/>
            <inertia ixx="0.217391101503" ixy="-0.00132873239126" ixz="-0.00228200226173" iyy="0.639432546734"
                     iyz="-0.00138078263145" izz="0.62414077654"/>
        </inertial>
    </link>
    <!-- Xacro:Properties -->
    <!-- [kg * m^2] -->
    <!-- [A] -->
    <link name="LF_HIP">
        <inertial>
            <origin rpy="0 0 0" xyz="0.064516258147 -0.003787101702 -0.000152184388"/>
            <mass value="1.42462064"/>
            <inertia ixx="0.00243023349564" ixy="-1.53023971e-05" ixz="-2.1819095354e-05" iyy="0.00230257239103"
                     iyz="2.6473021273e-05" izz="0.0019806759227"/>
        </inertial>
    </link>
    <!-- Hip joint -->
    <joint name="LF_HAA" type="revolute">
        <parent link="base"/>
        <child link="LF_HIP"/>
        <origin xyz="0.277 0.116 0.0"/>
        <axis xyz="1 0 0"/>
        <limit command_effort="40" current="10" effort="80" gear_velocity="10" lower="-9.42" upper="9.42"
               velocity="15"/>
        <dynamics damping="0.0" friction="0.0"/>
    </joint>
    <!-- Xacro:Properties -->
    <!-- [m] -->
    <!-- [A] -->
    <link name="LF_THIGH">
        <collision>
            <!-- KFE actuator -->
            <origin rpy="1.57079632679 0 0" xyz="0.0 0.069 -0.25"/>
            <geometry>
                <cylinder length="0.12" radius="0.06"/>
            </geometry>
        </collision>
        <collision>
            <!-- upper protector -->
            <origin rpy="1.71579632679 0 0" xyz="0 -0.005 0"/>
            <geometry>
                <cylinder length="0.12" radius="0.066"/>
            </geometry>
        </collision>
        <inertial>
            <origin rpy="0 0 0" xyz="-0.003897968082 0.054226618537 -0.214583373795"/>
            <mass value="1.634976467"/>
            <inertia ixx="0.0120367944369" ixy="6.762065206e-05" ixz="0.000287806340448" iyy="0.0120643637939"
                     iyz="-0.00140610131218" izz="0.00249422574881"/>
        </inertial>
    </link>
    <!-- Thigh joint -->
    <joint name="LF_HFE" type="revolute">
        <parent link="LF_HIP"/>
        <child link="LF_THIGH"/>
        <origin xyz="0.0635                    0.041                    0.0"/>
        <axis xyz="0 1 0"/>
        <limit command_effort="40" current="10" effort="80" gear_velocity="10" lower="-9.42" upper="9.42"
               velocity="15.0"/>
        <dynamics damping="0.0" friction="0.0"/>
    </joint>
    <!-- Xacro:Properties -->
    <!-- [m] -->
    <!-- [A] -->
    <link name="LF_SHANK">
        <inertial>
            <origin rpy="0 0 0" xyz="0.030816858139 -0.004617229294 0.000893125713"/>
            <mass value="0.207204302"/>
            <inertia ixx="0.0002104880248" ixy="-5.6750980345e-05" ixz="1.0127699391e-05" iyy="0.000676270210023"
                     iyz="-8.22869024e-07" izz="0.000545032674924"/>
        </inertial>
    </link>
    <!-- Shank joint -->
    <joint name="LF_KFE" type="revolute">
        <parent link="LF_THIGH"/>
        <child link="LF_SHANK"/>
        <origin xyz="0.0 0.109 -0.25"/>
        <axis xyz="0 1 0"/>
        <limit command_effort="40" current="10" effort="80" gear_velocity="10" lower="-9.42" upper="9.42"
               velocity="15.0"/>
        <dynamics damping="0.0" friction="0.0"/>
    </joint>
    <!-- Xacro:Properties -->
    <!-- [m] -->
    <!-- Shank to Adapter joint -->
    <joint name="LF_SHANK_TO_ADAPTER" type="fixed">
        <parent link="LF_SHANK"/>
        <child link="LF_ADAPTER"/>
        <origin rpy="0.0 0.0 0.0" xyz="0.1 -0.02 0.0"/>
    </joint>
    <!-- Adapter link -->
    <link name="LF_ADAPTER">
        <collision>
            <origin rpy="0 0 0" xyz="0 0 -0.160625"/>
            <geometry>
                <cylinder length="0.2" radius="0.015"/>
            </geometry>
            <material name="anymal_material"/>
        </collision>
        <inertial>
            <origin rpy="0 0 0" xyz="-8.66e-10 -1.472e-09 -0.244345749188"/>
            <mass value="0.140170767"/>
            <inertia ixx="0.00159938741862" ixy="-9.32e-13" ixz="1.039e-11" iyy="0.00159938741932" iyz="1.7563e-11"
                     izz="5.4423177329e-05"/>
        </inertial>
    </link>
    <!-- Adapter to Foot joint -->
    <joint name="LF_ADAPTER_TO_FOOT" type="fixed">
        <parent link="LF_ADAPTER"/>
        <child link="LF_FOOT"/>
        <origin rpy="0.0 0.0 0.0" xyz="0.0 0.0 -0.32125"/>
    </joint>
    <!-- Foot link -->
    <link name="LF_FOOT">
        <collision>
            <origin xyz="0 0 0.02325"/>
            <geometry>
                <sphere radius="0.031"/>
            </geometry>
        </collision>
    </link>
    <!-- Gazebo customization -->
    <gazebo reference="LF_FOOT">
        <kp>1000000.0</kp>
        <kd>100.0</kd>
        <mu1>0.8</mu1>
        <mu2>0.8</mu2>
    </gazebo>
    <!-- Xacro:Properties -->
    <!-- [kg * m^2] -->
    <!-- [A] -->
    <link name="RF_HIP">
        <inertial>
            <origin rpy="0 0 0" xyz="0.064516258147 0.003787101702 -0.000152184388"/>
            <mass value="1.42462064"/>
            <inertia ixx="0.00243023349564" ixy="1.53023971e-05" ixz="-2.1819095354e-05" iyy="0.00230257239103"
                     iyz="-2.6473021273e-05" izz="0.0019806759227"/>
        </inertial>
    </link>
    <!-- Hip joint -->
    <joint name="RF_HAA" type="revolute">
        <parent link="base"/>
        <child link="RF_HIP"/>
        <origin xyz="0.277 -0.116 0.0"/>
        <axis xyz="1 0 0"/>
        <limit command_effort="40" current="10" effort="80" gear_velocity="10" lower="-9.42" upper="9.42"
               velocity="15"/>
        <dynamics damping="0.0" friction="0.0"/>
    </joint>
    <!-- Xacro:Properties -->
    <!-- [m] -->
    <!-- [A] -->
    <link name="RF_THIGH">
        <collision>
            <!-- KFE actuator -->
            <origin rpy="1.57079632679 0 0" xyz="0.0 -0.069 -0.25"/>
            <geometry>
                <cylinder length="0.12" radius="0.06"/>
            </geometry>
        </collision>
        <collision>
            <!-- upper protector -->
            <origin rpy="-1.71579632679 0 0" xyz="0 0.005 0"/>
            <geometry>
                <cylinder length="0.12" radius="0.066"/>
            </geometry>
        </collision>
        <inertial>
            <origin rpy="0 0 0" xyz="-0.003897968082 -0.054226618537 -0.214583373795"/>
            <mass value="1.634976467"/>
            <inertia ixx="0.0120367944369" ixy="-6.762065206e-05" ixz="0.000287806340448" iyy="0.0120643637939"
                     iyz="0.00140610131218" izz="0.00249422574881"/>
        </inertial>
    </link>
    <!-- Thigh joint -->
    <joint name="RF_HFE" type="revolute">
        <parent link="RF_HIP"/>
        <child link="RF_THIGH"/>
        <origin xyz="0.0635                    -0.041                    0.0"/>
        <axis xyz="0 1 0"/>
        <limit command_effort="40" current="10" effort="80" gear_velocity="10" lower="-9.42" upper="9.42"
               velocity="15.0"/>
        <dynamics damping="0.0" friction="0.0"/>
    </joint>
    <!-- Xacro:Properties -->
    <!-- [m] -->
    <!-- [A] -->
    <link name="RF_SHANK">
        <inertial>
            <origin rpy="0 0 0" xyz="0.030816858139 0.004617229294 0.000893125713"/>
            <mass value="0.207204302"/>
            <inertia ixx="0.0002104880248" ixy="5.6750980345e-05" ixz="1.0127699391e-05" iyy="0.000676270210023"
                     iyz="8.22869024e-07" izz="0.000545032674924"/>
        </inertial>
    </link>
    <!-- Shank joint -->
    <joint name="RF_KFE" type="revolute">
        <parent link="RF_THIGH"/>
        <child link="RF_SHANK"/>
        <origin xyz="0.0 -0.109 -0.25"/>
        <axis xyz="0 1 0"/>
        <limit command_effort="40" current="10" effort="80" gear_velocity="10" lower="-9.42" upper="9.42"
               velocity="15.0"/>
        <dynamics damping="0.0" friction="0.0"/>
    </joint>
    <!-- Xacro:Properties -->
    <!-- [m] -->
    <!-- Shank to Adapter joint -->
    <joint name="RF_SHANK_TO_ADAPTER" type="fixed">
        <parent link="RF_SHANK"/>
        <child link="RF_ADAPTER"/>
        <origin rpy="-0.0 0.0 -0.0" xyz="0.1 0.02 0.0"/>
    </joint>
    <!-- Adapter link -->
    <link name="RF_ADAPTER">
        <collision>
            <origin rpy="0 0 0" xyz="0 0 -0.160625"/>
            <geometry>
                <cylinder length="0.2" radius="0.015"/>
            </geometry>
            <material name="anymal_material"/>
        </collision>
        <inertial>
            <origin rpy="0 0 0" xyz="-8.66e-10 -1.472e-09 -0.244345749188"/>
            <mass value="0.140170767"/>
            <inertia ixx="0.00159938741862" ixy="-9.32e-13" ixz="1.039e-11" iyy="0.00159938741932" iyz="1.7563e-11"
                     izz="5.4423177329e-05"/>
        </inertial>
    </link>
    <!-- Adapter to Foot joint -->
    <joint name="RF_ADAPTER_TO_FOOT" type="fixed">
        <parent link="RF_ADAPTER"/>
        <child link="RF_FOOT"/>
        <origin rpy="-0.0 0.0 -0.0" xyz="0.0 -0.0 -0.32125"/>
    </joint>
    <!-- Foot link -->
    <link name="RF_FOOT">
        <collision>
            <origin xyz="0 0 0.02325"/>
            <geometry>
                <sphere radius="0.031"/>
            </geometry>
        </collision>
    </link>
    <!-- Gazebo customization -->
    <gazebo reference="RF_FOOT">
        <kp>1000000.0</kp>
        <kd>100.0</kd>
        <mu1>0.8</mu1>
        <mu2>0.8</mu2>
    </gazebo>
    <!-- Xacro:Properties -->
    <!-- [kg * m^2] -->
    <!-- [A] -->
    <link name="LH_HIP">
        <inertial>
            <origin rpy="0 0 0" xyz="-0.064516258147 -0.003787101702 -0.000152184388"/>
            <mass value="1.42462064"/>
            <inertia ixx="0.00243023349564" ixy="1.53023971e-05" ixz="2.1819095354e-05" iyy="0.00230257239103"
                     iyz="2.6473021273e-05" izz="0.0019806759227"/>
        </inertial>
    </link>
    <!-- Hip joint -->
    <joint name="LH_HAA" type="revolute">
        <parent link="base"/>
        <child link="LH_HIP"/>
        <origin xyz="-0.277 0.116 0.0"/>
        <axis xyz="1 0 0"/>
        <limit command_effort="40" current="10" effort="80" gear_velocity="10" lower="-9.42" upper="9.42"
               velocity="15"/>
        <dynamics damping="0.0" friction="0.0"/>
    </joint>
    <!-- Xacro:Properties -->
    <!-- [m] -->
    <!-- [A] -->
    <link name="LH_THIGH">
        <collision>
            <!-- KFE actuator -->
            <origin rpy="1.57079632679 0 0" xyz="0.0 0.069 -0.25"/>
            <geometry>
                <cylinder length="0.12" radius="0.06"/>
            </geometry>
        </collision>
        <collision>
            <!-- upper protector -->
            <origin rpy="1.71579632679 0 0" xyz="0 -0.005 0"/>
            <geometry>
                <cylinder length="0.12" radius="0.066"/>
            </geometry>
        </collision>
        <inertial>
            <origin rpy="0 0 0" xyz="0.003897968082 0.054226618537 -0.214583373795"/>
            <mass value="1.634976467"/>
            <inertia ixx="0.0120367944369" ixy="-6.762065206e-05" ixz="-0.000287806340448" iyy="0.0120643637939"
                     iyz="-0.00140610131218" izz="0.00249422574881"/>
        </inertial>
    </link>
    <!-- Thigh joint -->
    <joint name="LH_HFE" type="revolute">
        <parent link="LH_HIP"/>
        <child link="LH_THIGH"/>
        <origin xyz="-0.0635                    0.041                    0.0"/>
        <axis xyz="0 1 0"/>
        <limit command_effort="40" current="10" effort="80" gear_velocity="10" lower="-9.42" upper="9.42"
               velocity="15.0"/>
        <dynamics damping="0.0" friction="0.0"/>
    </joint>
    <!-- Xacro:Properties -->
    <!-- [m] -->
    <!-- [A] -->
    <link name="LH_SHANK">
        <inertial>
            <origin rpy="0 0 0" xyz="-0.030816858139 -0.004617229294 0.000893125713"/>
            <mass value="0.207204302"/>
            <inertia ixx="0.0002104880248" ixy="5.6750980345e-05" ixz="-1.0127699391e-05" iyy="0.000676270210023"
                     iyz="-8.22869024e-07" izz="0.000545032674924"/>
        </inertial>
    </link>
    <!-- Shank joint -->
    <joint name="LH_KFE" type="revolute">
        <parent link="LH_THIGH"/>
        <child link="LH_SHANK"/>
        <origin xyz="-0.0 0.109 -0.25"/>
        <axis xyz="0 1 0"/>
        <limit command_effort="40" current="10" effort="80" gear_velocity="10" lower="-9.42" upper="9.42"
               velocity="15.0"/>
        <dynamics damping="0.0" friction="0.0"/>
    </joint>
    <!-- Xacro:Properties -->
    <!-- [m] -->
    <!-- Shank to Adapter joint -->
    <joint name="LH_SHANK_TO_ADAPTER" type="fixed">
        <parent link="LH_SHANK"/>
        <child link="LH_ADAPTER"/>
        <origin rpy="0.0 -0.0 -0.0" xyz="-0.1 -0.02 0.0"/>
    </joint>
    <!-- Adapter link -->
    <link name="LH_ADAPTER">
        <collision>
            <origin rpy="0 0 0" xyz="0 0 -0.160625"/>
            <geometry>
                <cylinder length="0.2" radius="0.015"/>
            </geometry>
            <material name="anymal_material"/>
        </collision>
        <inertial>
            <origin rpy="0 0 0" xyz="-8.66e-10 -1.472e-09 -0.244345749188"/>
            <mass value="0.140170767"/>
            <inertia ixx="0.00159938741862" ixy="-9.32e-13" ixz="1.039e-11" iyy="0.00159938741932" iyz="1.7563e-11"
                     izz="5.4423177329e-05"/>
        </inertial>
    </link>
    <!-- Adapter to Foot joint -->
    <joint name="LH_ADAPTER_TO_FOOT" type="fixed">
        <parent link="LH_ADAPTER"/>
        <child link="LH_FOOT"/>
        <origin rpy="0.0 -0.0 -0.0" xyz="-0.0 0.0 -0.32125"/>
    </joint>
    <!-- Foot link -->
    <link name="LH_FOOT">
        <collision>
            <origin xyz="0 0 0.02325"/>
            <geometry>
                <sphere radius="0.031"/>
            </geometry>
        </collision>
    </link>
    <!-- Gazebo customization -->
    <gazebo reference="LH_FOOT">
        <kp>1000000.0</kp>
        <kd>100.0</kd>
        <mu1>0.8</mu1>
        <mu2>0.8</mu2>
    </gazebo>
    <!-- Xacro:Properties -->
    <!-- [kg * m^2] -->
    <!-- [A] -->
    <link name="RH_HIP">
        <inertial>
            <origin rpy="0 0 0" xyz="-0.064516258147 0.003787101702 -0.000152184388"/>
            <mass value="1.42462064"/>
            <inertia ixx="0.00243023349564" ixy="-1.53023971e-05" ixz="2.1819095354e-05" iyy="0.00230257239103"
                     iyz="-2.6473021273e-05" izz="0.0019806759227"/>
        </inertial>
    </link>
    <!-- Hip joint -->
    <joint name="RH_HAA" type="revolute">
        <parent link="base"/>
        <child link="RH_HIP"/>
        <origin xyz="-0.277 -0.116 0.0"/>
        <axis xyz="1 0 0"/>
        <limit command_effort="40" current="10" effort="80" gear_velocity="10" lower="-9.42" upper="9.42"
               velocity="15"/>
        <dynamics damping="0.0" friction="0.0"/>
    </joint>
    <!-- Xacro:Properties -->
    <!-- [m] -->
    <!-- [A] -->
    <link name="RH_THIGH">
        <collision>
            <!-- KFE actuator -->
            <origin rpy="1.57079632679 0 0" xyz="0.0 -0.069 -0.25"/>
            <geometry>
                <cylinder length="0.12" radius="0.06"/>
            </geometry>
        </collision>
        <collision>
            <!-- upper protector -->
            <origin rpy="-1.71579632679 0 0" xyz="0 0.005 0"/>
            <geometry>
                <cylinder length="0.12" radius="0.066"/>
            </geometry>
        </collision>
        <inertial>
            <origin rpy="0 0 0" xyz="0.003897968082 -0.054226618537 -0.214583373795"/>
            <mass value="1.634976467"/>
            <inertia ixx="0.0120367944369" ixy="6.762065206e-05" ixz="-0.000287806340448" iyy="0.0120643637939"
                     iyz="0.00140610131218" izz="0.00249422574881"/>
        </inertial>
    </link>
    <!-- Thigh joint -->
    <joint name="RH_HFE" type="revolute">
        <parent link="RH_HIP"/>
        <child link="RH_THIGH"/>
        <origin xyz="-0.0635                    -0.041                    0.0"/>
        <axis xyz="0 1 0"/>
        <limit command_effort="40" current="10" effort="80" gear_velocity="10" lower="-9.42" upper="9.42"
               velocity="15.0"/>
        <dynamics damping="0.0" friction="0.0"/>
    </joint>
    <!-- Xacro:Properties -->
    <!-- [m] -->
    <!-- [A] -->
    <link name="RH_SHANK">
        <inertial>
            <origin rpy="0 0 0" xyz="-0.030816858139 0.004617229294 0.000893125713"/>
            <mass value="0.207204302"/>
            <inertia ixx="0.0002104880248" ixy="-5.6750980345e-05" ixz="-1.0127699391e-05" iyy="0.000676270210023"
                     iyz="8.22869024e-07" izz="0.000545032674924"/>
        </inertial>
    </link>
    <!-- Shank joint -->
    <joint name="RH_KFE" type="revolute">
        <parent link="RH_THIGH"/>
        <child link="RH_SHANK"/>
        <origin xyz="-0.0 -0.109 -0.25"/>
        <axis xyz="0 1 0"/>
        <limit command_effort="40" current="10" effort="80" gear_velocity="10" lower="-9.42" upper="9.42"
               velocity="15.0"/>
        <dynamics damping="0.0" friction="0.0"/>
    </joint>
    <!-- Xacro:Properties -->
    <!-- [m] -->
    <!-- Shank to Adapter joint -->
    <joint name="RH_SHANK_TO_ADAPTER" type="fixed">
        <parent link="RH_SHANK"/>
        <child link="RH_ADAPTER"/>
        <origin rpy="-0.0 -0.0 0.0" xyz="-0.1 0.02 0.0"/>
    </joint>
    <!-- Adapter link -->
    <link name="RH_ADAPTER">
        <collision>
            <origin rpy="0 0 0" xyz="0 0 -0.160625"/>
            <geometry>
                <cylinder length="0.2" radius="0.015"/>
            </geometry>
            <material name="anymal_material"/>
        </collision>
        <inertial>
            <origin rpy="0 0 0" xyz="-8.66e-10 -1.472e-09 -0.244345749188"/>
            <mass value="0.140170767"/>
            <inertia ixx="0.00159938741862" ixy="-9.32e-13" ixz="1.039e-11" iyy="0.00159938741932" iyz="1.7563e-11"
                     izz="5.4423177329e-05"/>
        </inertial>
    </link>
    <!-- Adapter to Foot joint -->
    <joint name="RH_ADAPTER_TO_FOOT" type="fixed">
        <parent link="RH_ADAPTER"/>
        <child link="RH_FOOT"/>
        <origin rpy="-0.0 -0.0 0.0" xyz="-0.0 -0.0 -0.32125"/>
    </joint>
    <!-- Foot link -->
    <link name="RH_FOOT">
        <collision>
            <origin xyz="0 0 0.02325"/>
            <geometry>
                <sphere radius="0.031"/>
            </geometry>
        </collision>
    </link>
    <!-- Gazebo customization -->
    <gazebo reference="RH_FOOT">
        <kp>1000000.0</kp>
        <kd>100.0</kd>
        <mu1>0.8</mu1>
        <mu2>0.8</mu2>
    </gazebo>
    <link name="imu_link">
        <inertial>
            <mass value="0.05"/>
            <origin xyz="0 0 0"/>
            <inertia ixx="1.60333333333e-05" ixy="0.0" ixz="0.0" iyy="2.80333333333e-05" iyz="0.0"
                     izz="1.60333333333e-05"/>
        </inertial>
    </link>
    <joint name="imu_joint" type="fixed">
        <parent link="base"/>
        <child link="imu_link"/>
        <origin rpy="0 3.14159265359 0" xyz="0.038 0.06245 0.1837"/>
    </joint>
    <!-- base to mount joint -->
    <joint name="base_to_velodyne_mount" type="fixed">
        <parent link="base"/>
        <child link="velodyne_mount"/>
        <origin rpy="0 0 0" xyz="-0.102 0.0 0.2896"/>
    </joint>
    <link name="velodyne_mount">
        <material name="anymal_material"/>
        <inertial>
            <!-- Values from CAD -->
            <origin rpy="0.0 0.0 0.0"
                    xyz="-0.003470719564                        -0.000437953244                         0.009296175974"/>
            <mass value="0.468309149"/>
            <inertia ixx="0.002023718043706" ixy="0.000007237377195" ixz="0.000088125050002" iyy="0.001843825349439"
                     iyz="-0.000005839762850" izz="0.002035845574943"/>
        </inertial>
    </link>
    <joint name="velodyne_mount_to_velodyne_axis_aligned" type="fixed">
        <origin rpy="0.0 0.0 -2.443460953" xyz="0.0 0.0 0.0"/>
        <parent link="velodyne_mount"/>
        <child link="velodyne_axis_aligned"/>
    </joint>
    <link name="velodyne_axis_aligned">
        <inertial>
            <mass value="0.589004276"/>
            <origin xyz="-0.000393930511                       0.000465473191                      -0.002216548208"/>
            <inertia ixx="0.000646625073623" ixy="-0.000010230485148" ixz="0.000006639631820" iyy="0.000643015385131"
                     iyz="-0.000007835650222" izz="0.000768918200999"/>
        </inertial>
        <collision>
            <origin rpy="0 0 0" xyz="0 0 0"/>
            <geometry>
                <cylinder length="0.0717" radius="0.0516"/>
            </geometry>
        </collision>
    </link>
    <joint name="velodyne_axis_aligned_to_velodyne" type="fixed">
        <origin rpy="0 0 0" xyz="0.0 0.0 0.0"/>
        <parent link="velodyne_axis_aligned"/>
        <child link="velodyne"/>
    </joint>
    <link name="velodyne">
        <inertial>
            <mass value="0.01"/>
            <origin xyz="0 0 0"/>
            <inertia ixx="1e-7" ixy="0" ixz="0" iyy="1e-7" iyz="0" izz="1e-7"/>
        </inertial>
    </link>
    <!-- Gazebo requires the velodyne_gazebo_plugins package -->
    <gazebo reference="velodyne">
        <sensor name="velodyne-VLP16" type="ray">
            <pose>0 0 0 0 0 0</pose>
            <visualize>false</visualize>
            <update_rate>10</update_rate>
            <ray>
                <scan>
                    <horizontal>
                        <samples>440</samples>
                        <resolution>1</resolution>
                        <min_angle>-3.14159265359</min_angle>
                        <max_angle>3.14159265359</max_angle>
                    </horizontal>
                    <vertical>
                        <samples>16</samples>
                        <resolution>1</resolution>
                        <min_angle>-0.261799387799</min_angle>
                        <max_angle>0.261799387799</max_angle>
                    </vertical>
                </scan>
                <range>
                    <min>0.3</min>
                    <max>131.0</max>
                    <resolution>0.001</resolution>
                </range>
                <noise>
                    <type>gaussian</type>
                    <mean>0.0</mean>
                    <stddev>0.0</stddev>
                </noise>
            </ray>
            <plugin filename="libgazebo_ros_velodyne_laser.so" name="gazebo_ros_laser_controller">
                <topicName>/velodyne/point_cloud</topicName>
                <frameName>velodyne</frameName>
                <min_range>0.9</min_range>
                <max_range>130.0</max_range>
                <gaussianNoise>0.008</gaussianNoise>
            </plugin>
        </sensor>
    </gazebo>
    <!-- Module attachment -->
    <joint name="base_to_handle_mount_front_axis_aligned" type="fixed">
        <parent link="base"/>
        <child link="handle_mount_front"/>
        <origin rpy="0.0 0.0 0.0" xyz="0.2692 0.0 0.1569"/>
    </joint>
    <!-- Mount module axis aligned -->
    <link name="handle_mount_front">
        <collision>
            <origin rpy="0 0 0" xyz="0.07 0.0 0.01"/>
            <geometry>
                <box size="0.139 0.152 0.097"/>
            </geometry>
            <material name="anymal_material"/>
        </collision>
        <inertial>
            <origin rpy="0 0 0" xyz="0 0 0"/>
            <mass value="0.001"/>
            <inertia ixx="0.00001" ixy="0.0" ixz="0.0" iyy="0.00001" iyz="0.0" izz="0.00001"/>
        </inertial>
    </link>
    <joint name="handle_mount_front_to_sensor_mount_axis_aligned" type="fixed">
        <parent link="handle_mount_front"/>
        <child link="handle_mount_front_sensor_mount_axis_aligned"/>
        <origin rpy="0 0 0" xyz="0.079 0.0 0.004724"/>
    </joint>
    <link name="handle_mount_front_sensor_mount_axis_aligned"/>
    <!-- Mount calibration joint -->
    <joint name="handle_mount_front_sensor_mount_axis_aligned_to_dual_realsense_mount" type="fixed">
        <parent link="handle_mount_front_sensor_mount_axis_aligned"/>
        <child link="dual_realsense_mount"/>
        <origin rpy="0.0 0.0 0.0" xyz="0.0 0.0 0.0"/>
    </joint>
    <!-- Mount link -->
    <link name="dual_realsense_mount">
        <inertial>
            <origin rpy="0 0 0"
                    xyz="0.054218447194                     -0.000000283793                      0.020065663731"/>
            <mass value="0.243898067"/>
            <inertia ixx="0.000779856566866" ixy="0.000000002160682" ixz="0.000147656791902" iyy="0.000570366165358"
                     iyz="0.000000000478926" izz="0.001154870002255"/>
        </inertial>
    </link>
    <!-- Mount tilting joint -->
    <joint name="dual_realsense_mount_to_dual_realsense_mount_tilted" type="fixed">
        <parent link="dual_realsense_mount"/>
        <child link="dual_realsense_mount_tilted"/>
        <origin rpy="0.0 0.0 0.0" xyz="0 0 0"/>
    </joint>
    <!-- Mount tilted link -->
    <link name="dual_realsense_mount_tilted">
        <inertial>
            <origin rpy="0 0 0" xyz="0.01295                      0.0                     -0.00657"/>
            <mass value="0.05491"/>
            <inertia ixx="0.000095582" ixy="0.0" ixz="-0.000001314" iyy="0.000033677" iyz="0.0" izz="0.000099687"/>
        </inertial>
    </link>
    <!-- INTEL REALSENSE MODEL: This official URDF from Intel can be used for verification of the ANYbotics model if desired. -->
    <!--
      <xacro:include filename="$(find realsense2_camera)/urdf/_d435.urdf.xacro"/>
      <sensor_d435 name="realsense_d435_front_INTEL" parent="dual_realsense_mount_tilted">
        <origin xyz="0.0043517095 0.0 -0.0368320164" rpy="0.0 ${37.0/ 180.0 * PI} 0.0"/>
      </sensor_d435>

      <sensor_d435 name="realsense_d435_front_forward_INTEL" parent="dual_realsense_mount_tilted">
        <origin xyz="0.0201066317 0.0 -0.0119413510" rpy="0.0 ${12.0/ 180.0 * PI} 0.0"/>
      </sensor_d435>
      -->
    <!-- Camera joint -->
    <!-- Is located between the two back screw holes at ground level. -->
    <joint name="dual_realsense_mount_tilted_to_realsense_d435_front_camera_axis_aligned" type="fixed">
        <parent link="dual_realsense_mount_tilted"/>
        <child link="realsense_d435_front_camera_axis_aligned"/>
        <origin rpy="0 0 0" xyz="0.013 0.0 -0.02362"/>
    </joint>
    <!-- Camera axis aligned link -->
    <link name="realsense_d435_front_camera_axis_aligned"/>
    <!-- Camera calibration joint -->
    <joint name="realsense_d435_front_camera_axis_aligned_to_camera" type="fixed">
        <parent link="realsense_d435_front_camera_axis_aligned"/>
        <child link="realsense_d435_front_camera"/>
        <origin rpy="0.0 0.645771823238 0.0" xyz="-0.0161525532 -0.0 -0.0063049601"/>
    </joint>
    <!-- Camera link -->
    <link name="realsense_d435_front_camera">
        <inertial>
            <origin rpy="0 0 0" xyz="0.011936651145 -0.000092349919 0.012257404184"/>
            <mass value="0.072"/>
            <inertia ixx="0.000045514558965" ixy="0.000000051943899" ixz="0.00000016511560" iyy="0.000006466822747"
                     iyz="-0.000000001668932" izz="0.000046225339262"/>
        </inertial>
    </link>
    <!-- Camera parent joint -->
    <!-- Frame lies on the left ir camera according to realsense2_camera urdf. -->
    <joint name="realsense_d435_front_camera_to_camera_parent" type="fixed">
        <parent link="realsense_d435_front_camera"/>
        <child link="realsense_d435_front_camera_parent"/>
        <origin rpy="0.0 0.0 0.0" xyz="0.02505 0.015 0.0125"/>
    </joint>
    <!-- Camera parent link -->
    <link name="realsense_d435_front_camera_parent"/>
    <!-- simulation or bagfile_is_played -->
    <!-- simulation -->
    <!-- Camera joint -->
    <!-- Is located between the two back screw holes at ground level. -->
    <joint name="dual_realsense_mount_tilted_to_realsense_d435_front_forward_camera_axis_aligned" type="fixed">
        <parent link="dual_realsense_mount_tilted"/>
        <child link="realsense_d435_front_forward_camera_axis_aligned"/>
        <origin rpy="0 0 0" xyz="0.013 0.0 -0.02362"/>
    </joint>
    <!-- Camera axis aligned link -->
    <link name="realsense_d435_front_forward_camera_axis_aligned"/>
    <!-- Camera calibration joint -->
    <joint name="realsense_d435_front_forward_camera_axis_aligned_to_camera" type="fixed">
        <parent link="realsense_d435_front_forward_camera_axis_aligned"/>
        <child link="realsense_d435_front_forward_camera"/>
        <origin rpy="0.0 0.209439510239 0.0" xyz="-0.0026136503 -0.0 0.0147671077"/>
    </joint>
    <!-- Camera link -->
    <link name="realsense_d435_front_forward_camera">
        <inertial>
            <origin rpy="0 0 0" xyz="0.011936651145 -0.000092349919 0.012257404184"/>
            <mass value="0.072"/>
            <inertia ixx="0.000045514558965" ixy="0.000000051943899" ixz="0.00000016511560" iyy="0.000006466822747"
                     iyz="-0.000000001668932" izz="0.000046225339262"/>
        </inertial>
    </link>
    <!-- Camera parent joint -->
    <!-- Frame lies on the left ir camera according to realsense2_camera urdf. -->
    <joint name="realsense_d435_front_forward_camera_to_camera_parent" type="fixed">
        <parent link="realsense_d435_front_forward_camera"/>
        <child link="realsense_d435_front_forward_camera_parent"/>
        <origin rpy="0.0 0.0 0.0" xyz="0.02505 0.015 0.0125"/>
    </joint>
    <!-- Camera parent link -->
    <link name="realsense_d435_front_forward_camera_parent"/>
    <!-- simulation or bagfile_is_played -->
    <!-- simulation -->
</robot>
