<?xml version="1.0" ?>
<!-- =================================================================================== -->
<!-- |    This document was autogenerated by xacro from hyqreal.urdf.xacro             | -->
<!-- |    EDITING THIS FILE BY HAND IS NOT RECOMMENDED                                 | -->
<!-- =================================================================================== -->
<robot name="hyqreal" xmlns:xacro="http://ros.org/wiki/xacro">
  <!-- standard distances -->
  <!-- <xacro:property name="d_lr" value="0.414"/>
	<xacro:property name="d_fh" value="0.747"/> -->
  <!-- 0.887 1.4192-->
  <!-- ============================ IMU KVH 1775 ========================
         The xacro macro xacro:kvh_1775_imu describes the KVH 1775 IMU,
         together with its frames of reference.
         The IMU has three axes oriented along the diagonal of the mounting
         screws at the bottom, as described at page 6 of the technical manual.
         These axes have three different origins for the sensing points, one
         per axis. Therefore, we define a common origin which is located at the
         average of these three. For completeness, we include the three exact
         axes as well. -->
  <material name="aluminum">
    <color rgba="0.5 0.5 0.5 1"/>
  </material>
  <!--xacro:include filename="$(find sensors_description)/urdfs/sensors/vlp16.urdf.xacro"/-->
  <gazebo>
    <plugin filename="libgazebo_ros_control.so" name="gazebo_ros_controller_manager">
      <robotNamespace>/hyqreal</robotNamespace>
      <robotSimType>dls_gazebo_interface/DlsRobotHwSim</robotSimType>
      <controlPeriod>0.004</controlPeriod>
    </plugin>
    <plugin filename="libgazebo_ros_p3d.so" name="gazebo_ros_p3d">
      <robotNamespace>/hyqreal</robotNamespace>
      <bodyName>trunk</bodyName>
      <topicName>ground_truth</topicName>
      <frameName>world</frameName>
      <xyzOffsets>0 0 0</xyzOffsets>
      <rpyOffsets>0 0 0</rpyOffsets>
      <gaussianNoise>0</gaussianNoise>
      <alwaysOn>true</alwaysOn>
      <updateRate>250.0</updateRate>
    </plugin>
  </gazebo>
  <!-- Floating-base Joint -->
  <joint name="floating_base" type="fixed">
    <origin rpy="0 0 0" xyz="0 0 0"/>
    <parent link="base_link"/>
    <child link="trunk"/>
  </joint>
  <!-- Links -->
  <!-- Footprint link -->
  <link name="base_link">
    <visual>
      <geometry>
        <cylinder length="0.01" radius="0.01"/>
      </geometry>
    </visual>
  </link>
  <!-- Trunk link -->
  <link name="trunk">
    <inertial>
      <origin xyz="-0.015 -0.00186 -0.03465"/>
      <mass value="59"/>
      <inertia ixx="1.498728" ixy="-0.007369" ixz="-0.189135" iyy="9.492381" iyz="0.000185" izz="9.012359"/>
    </inertial>
    <visual>
      <origin rpy="0 0 3.14159265359" xyz="0 0 0"/>
    </visual>
    <collision>
      <origin rpy="0 0 3.14159265359" xyz="0 0 0"/>
    </collision>
  </link>
  <gazebo reference="trunk">
    <kp>100000000.0</kp>
    <kd>100.0</kd>
    <mu1>1.5</mu1>
    <mu2>1.5</mu2>
    <maxVel>1.0</maxVel>
    <maxContacts>10</maxContacts>
    <minDepth>0.00</minDepth>
  </gazebo>
  <sensor name="trunk_contact_sensor" type="contact">
    <always_on>true</always_on>
    <update_rate>100.0</update_rate>
    <contact>
      <collision>trunk_collision</collision>
    </contact>
    <plugin filename="libgazebo_ros_bumper.so" name="trunk_bumper">
      <bumperTopicName>/trunk_sensor</bumperTopicName>
      <frameName>base_link</frameName>
    </plugin>
  </sensor>
  <!-- Joints -->
  <!-- HAA joint -->
  <joint name="lf_haa_joint" type="revolute">
    <origin rpy="3.14159265359 1.5707963268 0" xyz="0.4435 0.139 0"/>
    <parent link="trunk"/>
    <child link="lf_hipassembly"/>
    <axis xyz="0 0 1"/>
    <dynamics damping="0.1" friction="0"/>
    <limit effort="173.0" lower="-0.733038285838" upper="0.401425727959" velocity="12.0"/>
    <safety_controller k_position="50" k_velocity="10" soft_lower_limit="-0.733038285838" soft_upper_limit="0.401425727959"/>
  </joint>
  <!-- HFE joint -->
  <joint name="lf_hfe_joint" type="revolute">
    <origin rpy="1.5707963268 0 0" xyz="0 -0.117 0"/>
    <parent link="lf_hipassembly"/>
    <child link="lf_upperleg"/>
    <axis xyz="0 0 1"/>
    <dynamics damping="0.1" friction="0"/>
    <limit effort="208" lower="0.261799387799" upper="2.18166156499" velocity="12.0"/>
    <safety_controller k_position="50" k_velocity="10" soft_lower_limit="0.261799387799" soft_upper_limit="2.18166156499"/>
  </joint>
  <!-- KFE joint -->
  <joint name="lf_kfe_joint" type="revolute">
    <origin rpy="0 0 0" xyz="0.36 0 0"/>
    <parent link="lf_upperleg"/>
    <child link="lf_lowerleg"/>
    <axis xyz="0 0 1"/>
    <dynamics damping="0.1" friction="0"/>
    <limit effort="249" lower="-2.77001205584" upper="-0.669857366915" velocity="12.0"/>
    <safety_controller k_position="50.0" k_velocity="10.0" soft_lower_limit="-2.77001205584" soft_upper_limit="-0.669857366915"/>
  </joint>
  <!-- Foot joint -->
  <joint name="lf_foot_joint" type="fixed">
    <origin rpy="1.5707963268 0 -1.5707963268" xyz="0.38 0 0"/>
    <parent link="lf_lowerleg"/>
    <child link="lf_foot"/>
  </joint>
  <!-- Links -->
  <!-- Hip assembly link -->
  <link name="lf_hipassembly">
    <inertial>
      <origin xyz="-0.010027 -0.010608 0.003644"/>
      <mass value="4.973275"/>
      <inertia ixx="0.011231" ixy="-0.000592" ixz="0.000225" iyy="0.015768" iyz="0.000224" izz="0.016863"/>
    </inertial>
    <visual>
      <origin rpy="0 -1.5707963268 -1.5707963268" xyz="0 -0.046 0"/>
      <geometry>
         --&gt;
				
        <cylinder length="0.117" radius="0.0444"/>
      </geometry>
    </visual>
  </link>
  <!-- Upper leg link -->
  <link name="lf_upperleg">
    <inertial>
      <origin xyz="0.107987 -0.011459 -0.002121"/>
      <mass value="5.877927"/>
      <inertia ixx="0.016432" ixy="0.001863" ixz="0.003897" iyy="0.075737" iyz="-0.00024" izz="0.079267"/>
    </inertial>
    <visual>
      <origin rpy="0 0 0" xyz="0 0 0"/>
    </visual>
    <collision>
      <origin rpy="0 0 0" xyz="0 0 0"/>
    </collision>
  </link>
  <!-- Lower leg link -->
  <link name="lf_lowerleg">
    <inertial>
      <origin xyz="0.149302 -0.003801 -0.000624"/>
      <mass value="1.291954"/>
      <inertia ixx="0.001088" ixy="-0.000572" ixz="0.000118" iyy="0.029215" iyz="0.00046" izz="0.029772"/>
    </inertial>
    <visual>
      <origin rpy="0 0 0" xyz="0 0 0"/>

      <material name="white"/>
    </visual>
    <collision>
      <origin rpy="0 0 0" xyz="0 0 0"/>
    </collision>
  </link>
  <!-- Foot link -->
  <link name="lf_foot">
    <visual>
      <origin rpy="0.0 0.0 0.0" xyz="0.0 0.0 0.0"/>
      <geometry>
        <sphere radius="0.032"/>
      </geometry>
      <material name="black"/>
    </visual>
    <collision>
      <origin rpy="0 0 0" xyz="0 0 0"/>
      <geometry>
        <sphere radius="0.032"/>
      </geometry>
    </collision>
  </link>
  <!-- Hip assembly -->
  <transmission name="lf_haa_trans">
    <type>transmission_interface/SimpleTransmission</type>
    <joint name="lf_haa_joint">
      <hardwareInterface>EffortJointInterface</hardwareInterface>
    </joint>
    <actuator name="lf_haa_motor">
      <mechanicalReduction>1</mechanicalReduction>
    </actuator>
  </transmission>
  <!-- Upper leg -->
  <transmission name="lf_hfe_trans">
    <type>transmission_interface/SimpleTransmission</type>
    <joint name="lf_hfe_joint">
      <hardwareInterface>EffortJointInterface</hardwareInterface>
    </joint>
    <actuator name="lf_hfe_motor">
      <mechanicalReduction>1</mechanicalReduction>
    </actuator>
  </transmission>
  <!-- Lower leg -->
  <transmission name="lf_kfe_trans">
    <type>transmission_interface/SimpleTransmission</type>
    <joint name="lf_kfe_joint">
      <hardwareInterface>EffortJointInterface</hardwareInterface>
    </joint>
    <actuator name="lf_kfe_motor">
      <mechanicalReduction>1</mechanicalReduction>
    </actuator>
  </transmission>
  <gazebo reference="lf_haa_joint">
    <provideFeedback>true</provideFeedback>
  </gazebo>
  <gazebo reference="lf_kfe_joint">
    <provideFeedback>true</provideFeedback>
  </gazebo>
  <gazebo reference="lf_hfe_joint">
    <provideFeedback>true</provideFeedback>
  </gazebo>
  <gazebo reference="lf_upperleg">
    <kp>100000000.0</kp>
    <kd>100.0</kd>
    <mu1>1.5</mu1>
    <mu2>1.5</mu2>
    <maxVel>1.0</maxVel>
    <minDepth>0.00</minDepth>
  </gazebo>
  <gazebo reference="lf_lowerleg">
    <kp>100000000.0</kp>
    <kd>100.0</kd>
    <mu1>1.0</mu1>
    <mu2>1.0</mu2>
    <maxVel>1.0</maxVel>
    <maxContacts>1</maxContacts>
    <minDepth>0.00</minDepth>
    <sensor name="lf_shin_contact_sensor" type="contact">
      <always_on>true</always_on>
      <update_rate>250.0</update_rate>
      <contact>
        <collision>lf_lowerleg_collision</collision>
      </contact>
      <!-- the sensor readings in terms of force torques are expressed in the lowerleg frame
                    because gazebo lumps the fake footframe with the real parent link, the normals are in the world frame-->
      <plugin filename="libgazebo_ros_bumper.so" name="lf_shin_bumper">
        <bumperTopicName>/hyqreal/lf_shin_bumper</bumperTopicName>
      </plugin>
    </sensor>
  </gazebo>
  <gazebo reference="lf_foot">
    <kp>1000000.0</kp>
    <kd>100.0</kd>
    <mu1>1.0</mu1>
    <mu2>1.0</mu2>
    <maxVel>1.0</maxVel>
    <maxContacts>1</maxContacts>
    <sensor name="lf_foot_contact_sensor" type="contact">
      <always_on>true</always_on>
      <update_rate>250.0</update_rate>
      <contact>
        <collision>lf_lowerleg_fixed_joint_lump__lf_foot_collision_1</collision>
      </contact>
      <!-- the sensor readings in terms of force torques are expressed in the lowerleg frame
                    because gazebo lumps the fake footframe with the real parent link, the normals are in the world frame-->
      <plugin filename="libgazebo_ros_bumper.so" name="lf_foot_bumper">
        <bumperTopicName>/hyqreal/lf_foot_bumper</bumperTopicName>
        <robotNamespace>hyqreal</robotNamespace>
      </plugin>
    </sensor>
    <material>Gazebo/Black</material>
  </gazebo>
  <!-- Joints -->
  <!-- HAA joint -->
  <joint name="rf_haa_joint" type="revolute">
    <origin rpy="0 1.5707963268 0" xyz="0.4435 -0.139 0"/>
    <parent link="trunk"/>
    <child link="rf_hipassembly"/>
    <axis xyz="0 0 1"/>
    <dynamics damping="0.1" friction="0"/>
    <limit effort="173.0" lower="-0.733038285838" upper="0.401425727959" velocity="12.0"/>
    <safety_controller k_position="50" k_velocity="10" soft_lower_limit="-0.733038285838" soft_upper_limit="0.401425727959"/>
  </joint>
  <!-- HFE joint -->
  <joint name="rf_hfe_joint" type="revolute">
    <origin rpy="-1.5707963268 0 0" xyz="0 -0.117 0"/>
    <parent link="rf_hipassembly"/>
    <child link="rf_upperleg"/>
    <axis xyz="0 0 1"/>
    <dynamics damping="0.1" friction="0"/>
    <limit effort="208" lower="0.261799387799" upper="2.18166156499" velocity="12.0"/>
    <safety_controller k_position="50" k_velocity="10" soft_lower_limit="0.261799387799" soft_upper_limit="2.18166156499"/>
  </joint>
  <!-- KFE joint -->
  <joint name="rf_kfe_joint" type="revolute">
    <origin rpy="0 0 0" xyz="0.36 0 0"/>
    <parent link="rf_upperleg"/>
    <child link="rf_lowerleg"/>
    <axis xyz="0 0 1"/>
    <dynamics damping="0.1" friction="0"/>
    <limit effort="249" lower="-2.77001205584" upper="-0.669857366915" velocity="12.0"/>
    <safety_controller k_position="50.0" k_velocity="10.0" soft_lower_limit="-2.77001205584" soft_upper_limit="-0.669857366915"/>
  </joint>
  <!-- Foot joint -->
  <joint name="rf_foot_joint" type="fixed">
    <origin rpy="1.5707963268 0 -1.5707963268" xyz="0.38 0 0"/>
    <parent link="rf_lowerleg"/>
    <child link="rf_foot"/>
  </joint>
  <!-- Links -->
  <!-- Hip assembly link -->
  <link name="rf_hipassembly">
    <inertial>
      <origin xyz="-0.010027 -0.010608 0.003644"/>
      <mass value="4.973275"/>
      <inertia ixx="0.011231" ixy="-0.000592" ixz="0.000225" iyy="0.015768" iyz="0.000224" izz="0.016863"/>
    </inertial>
    <visual>
      <origin rpy="0 -1.5707963268 -1.5707963268" xyz="0 -0.046 0"/>
      <geometry>
         --&gt;
				
        <cylinder length="0.117" radius="0.0444"/>
      </geometry>
    </visual>
  </link>
  <!-- Upper leg link -->
  <link name="rf_upperleg">
    <inertial>
      <origin xyz="0.107987 -0.011459 0.002121"/>
      <mass value="5.877927"/>
      <inertia ixx="0.016432" ixy="0.001863" ixz="-0.003897" iyy="0.075737" iyz="0.00024" izz="0.079267"/>
    </inertial>
    <visual>
      <origin rpy="0 0 0" xyz="0 0 0"/>
    </visual>
    <collision>
      <origin rpy="0 0 0" xyz="0 0 0"/>
    </collision>
  </link>
  <!-- Lower leg link -->
  <link name="rf_lowerleg">
    <inertial>
      <origin xyz="0.149302 -0.003801 -0.000624"/>
      <mass value="1.291954"/>
      <inertia ixx="0.001088" ixy="-0.000572" ixz="0.000118" iyy="0.029215" iyz="0.00046" izz="0.029772"/>
    </inertial>
    <visual>
      <origin rpy="0 0 0" xyz="0 0 0"/>
      <material name="white"/>
    </visual>
    <collision>
      <origin rpy="0 0 0" xyz="0 0 0"/>
    </collision>
  </link>
  <!-- Foot link -->
  <link name="rf_foot">
    <visual>
      <origin rpy="0.0 0.0 0.0" xyz="0.0 0.0 0.0"/>
      <geometry>
        <sphere radius="0.032"/>
      </geometry>
      <material name="black"/>
    </visual>
    <collision>
      <origin rpy="0 0 0" xyz="0 0 0"/>
      <geometry>
        <sphere radius="0.032"/>
      </geometry>
    </collision>
  </link>
  <!-- Hip assembly -->
  <transmission name="rf_haa_trans">
    <type>transmission_interface/SimpleTransmission</type>
    <joint name="rf_haa_joint">
      <hardwareInterface>EffortJointInterface</hardwareInterface>
    </joint>
    <actuator name="rf_haa_motor">
      <mechanicalReduction>1</mechanicalReduction>
    </actuator>
  </transmission>
  <!-- Upper leg -->
  <transmission name="rf_hfe_trans">
    <type>transmission_interface/SimpleTransmission</type>
    <joint name="rf_hfe_joint">
      <hardwareInterface>EffortJointInterface</hardwareInterface>
    </joint>
    <actuator name="rf_hfe_motor">
      <mechanicalReduction>1</mechanicalReduction>
    </actuator>
  </transmission>
  <!-- Lower leg -->
  <transmission name="rf_kfe_trans">
    <type>transmission_interface/SimpleTransmission</type>
    <joint name="rf_kfe_joint">
      <hardwareInterface>EffortJointInterface</hardwareInterface>
    </joint>
    <actuator name="rf_kfe_motor">
      <mechanicalReduction>1</mechanicalReduction>
    </actuator>
  </transmission>
  <gazebo reference="rf_haa_joint">
    <provideFeedback>true</provideFeedback>
  </gazebo>
  <gazebo reference="rf_kfe_joint">
    <provideFeedback>true</provideFeedback>
  </gazebo>
  <gazebo reference="rf_hfe_joint">
    <provideFeedback>true</provideFeedback>
  </gazebo>
  <gazebo reference="rf_upperleg">
    <kp>100000000.0</kp>
    <kd>100.0</kd>
    <mu1>1.5</mu1>
    <mu2>1.5</mu2>
    <maxVel>1.0</maxVel>
    <minDepth>0.00</minDepth>
  </gazebo>
  <gazebo reference="rf_lowerleg">
    <kp>100000000.0</kp>
    <kd>100.0</kd>
    <mu1>1.0</mu1>
    <mu2>1.0</mu2>
    <maxVel>1.0</maxVel>
    <maxContacts>1</maxContacts>
    <minDepth>0.00</minDepth>
    <sensor name="rf_shin_contact_sensor" type="contact">
      <always_on>true</always_on>
      <update_rate>250.0</update_rate>
      <contact>
        <collision>rf_lowerleg_collision</collision>
      </contact>
      <!-- the sensor readings in terms of force torques are expressed in the lowerleg frame
                    because gazebo lumps the fake footframe with the real parent link, the normals are in the world frame-->
      <plugin filename="libgazebo_ros_bumper.so" name="rf_shin_bumper">
        <bumperTopicName>/hyqreal/rf_shin_bumper</bumperTopicName>
      </plugin>
    </sensor>
  </gazebo>
  <gazebo reference="rf_foot">
    <kp>1000000.0</kp>
    <kd>100.0</kd>
    <mu1>1.0</mu1>
    <mu2>1.0</mu2>
    <maxVel>1.0</maxVel>
    <maxContacts>1</maxContacts>
    <sensor name="rf_foot_contact_sensor" type="contact">
      <always_on>true</always_on>
      <update_rate>250.0</update_rate>
      <contact>
        <collision>rf_lowerleg_fixed_joint_lump__rf_foot_collision_1</collision>
      </contact>
      <!-- the sensor readings in terms of force torques are expressed in the lowerleg frame
                    because gazebo lumps the fake footframe with the real parent link, the normals are in the world frame-->
      <plugin filename="libgazebo_ros_bumper.so" name="rf_foot_bumper">
        <bumperTopicName>/hyqreal/rf_foot_bumper</bumperTopicName>
        <robotNamespace>hyqreal</robotNamespace>
      </plugin>
    </sensor>
    <material>Gazebo/Black</material>
  </gazebo>
  <!-- Joints -->
  <!-- HAA joint -->
  <joint name="lh_haa_joint" type="revolute">
    <origin rpy="3.14159265359 1.5707963268 0" xyz="-0.4435 0.139 0"/>
    <parent link="trunk"/>
    <child link="lh_hipassembly"/>
    <axis xyz="0 0 1"/>
    <dynamics damping="0.1" friction="0"/>
    <limit effort="173.0" lower="-0.733038285838" upper="0.401425727959" velocity="12.0"/>
    <safety_controller k_position="50" k_velocity="10" soft_lower_limit="-0.733038285838" soft_upper_limit="0.401425727959"/>
  </joint>
  <!-- HFE joint -->
  <joint name="lh_hfe_joint" type="revolute">
    <origin rpy="1.5707963268 0 0" xyz="0 -0.117 0"/>
    <parent link="lh_hipassembly"/>
    <child link="lh_upperleg"/>
    <axis xyz="0 0 1"/>
    <dynamics damping="0.1" friction="0"/>
    <limit effort="208" lower="0.261799387799" upper="2.18166156499" velocity="12.0"/>
    <safety_controller k_position="50" k_velocity="10" soft_lower_limit="0.261799387799" soft_upper_limit="2.18166156499"/>
  </joint>
  <!-- KFE joint -->
  <joint name="lh_kfe_joint" type="revolute">
    <origin rpy="0 0 0" xyz="0.36 0 0"/>
    <parent link="lh_upperleg"/>
    <child link="lh_lowerleg"/>
    <axis xyz="0 0 1"/>
    <dynamics damping="0.1" friction="0"/>
    <limit effort="249" lower="-2.77001205584" upper="-0.669857366915" velocity="12.0"/>
    <safety_controller k_position="50.0" k_velocity="10.0" soft_lower_limit="-2.77001205584" soft_upper_limit="-0.669857366915"/>
  </joint>
  <!-- Foot joint -->
  <joint name="lh_foot_joint" type="fixed">
    <origin rpy="1.5707963268 0 -1.5707963268" xyz="0.38 0 0"/>
    <parent link="lh_lowerleg"/>
    <child link="lh_foot"/>
  </joint>
  <!-- Links -->
  <!-- Hip assembly link -->
  <link name="lh_hipassembly">
    <inertial>
      <origin xyz="-0.010027 -0.010608 0.003644"/>
      <mass value="4.973275"/>
      <inertia ixx="0.011231" ixy="-0.000592" ixz="0.000225" iyy="0.015768" iyz="0.000224" izz="0.016863"/>
    </inertial>
    <visual>
      <origin rpy="0 -1.5707963268 -1.5707963268" xyz="0 -0.046 0"/>
      <geometry>
         --&gt;
				
        <cylinder length="0.117" radius="0.0444"/>
      </geometry>
    </visual>
  </link>
  <!-- Upper leg link -->
  <link name="lh_upperleg">
    <inertial>
      <origin xyz="0.107987 -0.011459 -0.002121"/>
      <mass value="5.877927"/>
      <inertia ixx="0.016432" ixy="0.001863" ixz="0.003897" iyy="0.075737" iyz="-0.00024" izz="0.079267"/>
    </inertial>
    <visual>
      <origin rpy="0 0 0" xyz="0 0 0"/>
    </visual>
    <collision>
      <origin rpy="0 0 0" xyz="0 0 0"/>
    </collision>
  </link>
  <!-- Lower leg link -->
  <link name="lh_lowerleg">
    <inertial>
      <origin xyz="0.149302 -0.003801 -0.000624"/>
      <mass value="1.291954"/>
      <inertia ixx="0.001088" ixy="-0.000572" ixz="0.000118" iyy="0.029215" iyz="0.00046" izz="0.029772"/>
    </inertial>
    <visual>
      <origin rpy="0 0 0" xyz="0 0 0"/>
      <material name="white"/>
    </visual>
    <collision>
      <origin rpy="0 0 0" xyz="0 0 0"/>
    </collision>
  </link>
  <!-- Foot link -->
  <link name="lh_foot">
    <visual>
      <origin rpy="0.0 0.0 0.0" xyz="0.0 0.0 0.0"/>
      <geometry>
        <sphere radius="0.032"/>
      </geometry>
      <material name="black"/>
    </visual>
    <collision>
      <origin rpy="0 0 0" xyz="0 0 0"/>
      <geometry>
        <sphere radius="0.032"/>
      </geometry>
    </collision>
  </link>
  <!-- Hip assembly -->
  <transmission name="lh_haa_trans">
    <type>transmission_interface/SimpleTransmission</type>
    <joint name="lh_haa_joint">
      <hardwareInterface>EffortJointInterface</hardwareInterface>
    </joint>
    <actuator name="lh_haa_motor">
      <mechanicalReduction>1</mechanicalReduction>
    </actuator>
  </transmission>
  <!-- Upper leg -->
  <transmission name="lh_hfe_trans">
    <type>transmission_interface/SimpleTransmission</type>
    <joint name="lh_hfe_joint">
      <hardwareInterface>EffortJointInterface</hardwareInterface>
    </joint>
    <actuator name="lh_hfe_motor">
      <mechanicalReduction>1</mechanicalReduction>
    </actuator>
  </transmission>
  <!-- Lower leg -->
  <transmission name="lh_kfe_trans">
    <type>transmission_interface/SimpleTransmission</type>
    <joint name="lh_kfe_joint">
      <hardwareInterface>EffortJointInterface</hardwareInterface>
    </joint>
    <actuator name="lh_kfe_motor">
      <mechanicalReduction>1</mechanicalReduction>
    </actuator>
  </transmission>
  <gazebo reference="lh_haa_joint">
    <provideFeedback>true</provideFeedback>
  </gazebo>
  <gazebo reference="lh_kfe_joint">
    <provideFeedback>true</provideFeedback>
  </gazebo>
  <gazebo reference="lh_hfe_joint">
    <provideFeedback>true</provideFeedback>
  </gazebo>
  <gazebo reference="lh_upperleg">
    <kp>100000000.0</kp>
    <kd>100.0</kd>
    <mu1>1.5</mu1>
    <mu2>1.5</mu2>
    <maxVel>1.0</maxVel>
    <minDepth>0.00</minDepth>
  </gazebo>
  <gazebo reference="lh_lowerleg">
    <kp>100000000.0</kp>
    <kd>100.0</kd>
    <mu1>1.0</mu1>
    <mu2>1.0</mu2>
    <maxVel>1.0</maxVel>
    <maxContacts>1</maxContacts>
    <minDepth>0.00</minDepth>
    <sensor name="lh_shin_contact_sensor" type="contact">
      <always_on>true</always_on>
      <update_rate>250.0</update_rate>
      <contact>
        <collision>lh_lowerleg_collision</collision>
      </contact>
      <!-- the sensor readings in terms of force torques are expressed in the lowerleg frame
                    because gazebo lumps the fake footframe with the real parent link, the normals are in the world frame-->
      <plugin filename="libgazebo_ros_bumper.so" name="lh_shin_bumper">
        <bumperTopicName>/hyqreal/lh_shin_bumper</bumperTopicName>
      </plugin>
    </sensor>
  </gazebo>
  <gazebo reference="lh_foot">
    <kp>1000000.0</kp>
    <kd>100.0</kd>
    <mu1>1.0</mu1>
    <mu2>1.0</mu2>
    <maxVel>1.0</maxVel>
    <maxContacts>1</maxContacts>
    <sensor name="lh_foot_contact_sensor" type="contact">
      <always_on>true</always_on>
      <update_rate>250.0</update_rate>
      <contact>
        <collision>lh_lowerleg_fixed_joint_lump__lh_foot_collision_1</collision>
      </contact>
      <!-- the sensor readings in terms of force torques are expressed in the lowerleg frame
                    because gazebo lumps the fake footframe with the real parent link, the normals are in the world frame-->
      <plugin filename="libgazebo_ros_bumper.so" name="lh_foot_bumper">
        <bumperTopicName>/hyqreal/lh_foot_bumper</bumperTopicName>
        <robotNamespace>hyqreal</robotNamespace>
      </plugin>
    </sensor>
    <material>Gazebo/Black</material>
  </gazebo>
  <!-- Joints -->
  <!-- HAA joint -->
  <joint name="rh_haa_joint" type="revolute">
    <origin rpy="0 1.5707963268 0" xyz="-0.4435 -0.139 0"/>
    <parent link="trunk"/>
    <child link="rh_hipassembly"/>
    <axis xyz="0 0 1"/>
    <dynamics damping="0.1" friction="0"/>
    <limit effort="173.0" lower="-0.733038285838" upper="0.401425727959" velocity="12.0"/>
    <safety_controller k_position="50" k_velocity="10" soft_lower_limit="-0.733038285838" soft_upper_limit="0.401425727959"/>
  </joint>
  <!-- HFE joint -->
  <joint name="rh_hfe_joint" type="revolute">
    <origin rpy="-1.5707963268 0 0" xyz="0 -0.117 0"/>
    <parent link="rh_hipassembly"/>
    <child link="rh_upperleg"/>
    <axis xyz="0 0 1"/>
    <dynamics damping="0.1" friction="0"/>
    <limit effort="208" lower="0.261799387799" upper="2.18166156499" velocity="12.0"/>
    <safety_controller k_position="50" k_velocity="10" soft_lower_limit="0.261799387799" soft_upper_limit="2.18166156499"/>
  </joint>
  <!-- KFE joint -->
  <joint name="rh_kfe_joint" type="revolute">
    <origin rpy="0 0 0" xyz="0.36 0 0"/>
    <parent link="rh_upperleg"/>
    <child link="rh_lowerleg"/>
    <axis xyz="0 0 1"/>
    <dynamics damping="0.1" friction="0"/>
    <limit effort="249" lower="-2.77001205584" upper="-0.669857366915" velocity="12.0"/>
    <safety_controller k_position="50.0" k_velocity="10.0" soft_lower_limit="-2.77001205584" soft_upper_limit="-0.669857366915"/>
  </joint>
  <!-- Foot joint -->
  <joint name="rh_foot_joint" type="fixed">
    <origin rpy="1.5707963268 0 -1.5707963268" xyz="0.38 0 0"/>
    <parent link="rh_lowerleg"/>
    <child link="rh_foot"/>
  </joint>
  <!-- Links -->
  <!-- Hip assembly link -->
  <link name="rh_hipassembly">
    <inertial>
      <origin xyz="-0.010027 -0.010608 0.003644"/>
      <mass value="4.973275"/>
      <inertia ixx="0.011231" ixy="-0.000592" ixz="0.000225" iyy="0.015768" iyz="0.000224" izz="0.016863"/>
    </inertial>
    <visual>
      <origin rpy="0 -1.5707963268 -1.5707963268" xyz="0 -0.046 0"/>
      <geometry>
         --&gt;
				
        <cylinder length="0.117" radius="0.0444"/>
      </geometry>
    </visual>
  </link>
  <!-- Upper leg link -->
  <link name="rh_upperleg">
    <inertial>
      <origin xyz="0.107987 -0.011459 0.002121"/>
      <mass value="5.877927"/>
      <inertia ixx="0.016432" ixy="0.001863" ixz="-0.003897" iyy="0.075737" iyz="0.00024" izz="0.079267"/>
    </inertial>
    <visual>
      <origin rpy="0 0 0" xyz="0 0 0"/>
    </visual>
    <collision>
      <origin rpy="0 0 0" xyz="0 0 0"/>
    </collision>
  </link>
  <!-- Lower leg link -->
  <link name="rh_lowerleg">
    <inertial>
      <origin xyz="0.149302 -0.003801 -0.000624"/>
      <mass value="1.291954"/>
      <inertia ixx="0.001088" ixy="-0.000572" ixz="0.000118" iyy="0.029215" iyz="0.00046" izz="0.029772"/>
    </inertial>
    <visual>
      <origin rpy="0 0 0" xyz="0 0 0"/>
      <material name="white"/>
    </visual>
    <collision>
      <origin rpy="0 0 0" xyz="0 0 0"/>
    </collision>
  </link>
  <!-- Foot link -->
  <link name="rh_foot">
    <visual>
      <origin rpy="0.0 0.0 0.0" xyz="0.0 0.0 0.0"/>
      <geometry>
        <sphere radius="0.032"/>
      </geometry>
      <material name="black"/>
    </visual>
    <collision>
      <origin rpy="0 0 0" xyz="0 0 0"/>
      <geometry>
        <sphere radius="0.032"/>
      </geometry>
    </collision>
  </link>
  <!-- Hip assembly -->
  <transmission name="rh_haa_trans">
    <type>transmission_interface/SimpleTransmission</type>
    <joint name="rh_haa_joint">
      <hardwareInterface>EffortJointInterface</hardwareInterface>
    </joint>
    <actuator name="rh_haa_motor">
      <mechanicalReduction>1</mechanicalReduction>
    </actuator>
  </transmission>
  <!-- Upper leg -->
  <transmission name="rh_hfe_trans">
    <type>transmission_interface/SimpleTransmission</type>
    <joint name="rh_hfe_joint">
      <hardwareInterface>EffortJointInterface</hardwareInterface>
    </joint>
    <actuator name="rh_hfe_motor">
      <mechanicalReduction>1</mechanicalReduction>
    </actuator>
  </transmission>
  <!-- Lower leg -->
  <transmission name="rh_kfe_trans">
    <type>transmission_interface/SimpleTransmission</type>
    <joint name="rh_kfe_joint">
      <hardwareInterface>EffortJointInterface</hardwareInterface>
    </joint>
    <actuator name="rh_kfe_motor">
      <mechanicalReduction>1</mechanicalReduction>
    </actuator>
  </transmission>
  <gazebo reference="rh_haa_joint">
    <provideFeedback>true</provideFeedback>
  </gazebo>
  <gazebo reference="rh_kfe_joint">
    <provideFeedback>true</provideFeedback>
  </gazebo>
  <gazebo reference="rh_hfe_joint">
    <provideFeedback>true</provideFeedback>
  </gazebo>
  <gazebo reference="rh_upperleg">
    <kp>100000000.0</kp>
    <kd>100.0</kd>
    <mu1>1.5</mu1>
    <mu2>1.5</mu2>
    <maxVel>1.0</maxVel>
    <minDepth>0.00</minDepth>
  </gazebo>
  <gazebo reference="rh_lowerleg">
    <kp>100000000.0</kp>
    <kd>100.0</kd>
    <mu1>1.0</mu1>
    <mu2>1.0</mu2>
    <maxVel>1.0</maxVel>
    <maxContacts>1</maxContacts>
    <minDepth>0.00</minDepth>
    <sensor name="rh_shin_contact_sensor" type="contact">
      <always_on>true</always_on>
      <update_rate>250.0</update_rate>
      <contact>
        <collision>rh_lowerleg_collision</collision>
      </contact>
      <!-- the sensor readings in terms of force torques are expressed in the lowerleg frame
                    because gazebo lumps the fake footframe with the real parent link, the normals are in the world frame-->
      <plugin filename="libgazebo_ros_bumper.so" name="rh_shin_bumper">
        <bumperTopicName>/hyqreal/rh_shin_bumper</bumperTopicName>
      </plugin>
    </sensor>
  </gazebo>
  <gazebo reference="rh_foot">
    <kp>1000000.0</kp>
    <kd>100.0</kd>
    <mu1>1.0</mu1>
    <mu2>1.0</mu2>
    <maxVel>1.0</maxVel>
    <maxContacts>1</maxContacts>
    <sensor name="rh_foot_contact_sensor" type="contact">
      <always_on>true</always_on>
      <update_rate>250.0</update_rate>
      <contact>
        <collision>rh_lowerleg_fixed_joint_lump__rh_foot_collision_1</collision>
      </contact>
      <!-- the sensor readings in terms of force torques are expressed in the lowerleg frame
                    because gazebo lumps the fake footframe with the real parent link, the normals are in the world frame-->
      <plugin filename="libgazebo_ros_bumper.so" name="rh_foot_bumper">
        <bumperTopicName>/hyqreal/rh_foot_bumper</bumperTopicName>
        <robotNamespace>hyqreal</robotNamespace>
      </plugin>
    </sensor>
    <material>Gazebo/Black</material>
  </gazebo>
  <!-- Joint connecting the mount point of the IMU to the robot -->
  <joint name="trunk_imu_mount_joint" type="fixed">
    <origin rpy="3.14159265359 0 0" xyz="-0.1098 0 -0.045"/>
    <parent link="trunk"/>
    <child link="trunk_imu_mount"/>
  </joint>
  <!-- Fake joint connecting the mount point of the IMU to the
                     average sensing frame of the IMU -->
  <joint name="trunk_imu_joint" type="fixed">
    <origin rpy="0 0 0" xyz="-0.017066667 -0.013 0.038366667"/>
    <parent link="trunk_imu_mount"/>
    <child link="trunk_imu"/>
  </joint>
  <!-- Fake joint connecting the mount point of the IMU to
                     the sensing point for the x-axis -->
  <joint name="trunk_imu_sensing_point_x_joint" type="fixed">
    <origin rpy="0 0 0" xyz="0 -0.0263 0.0336"/>
    <parent link="trunk_imu_mount"/>
    <child link="trunk_imu_sensing_point_x"/>
  </joint>
  <!-- Fake joint connecting the mount point of the IMU to
                     the sensing point for the x-axis -->
  <joint name="trunk_imu_sensing_point_y_joint" type="fixed">
    <origin rpy="0 0 0" xyz="-0.0256 -0.0121 0.0372"/>
    <parent link="trunk_imu_mount"/>
    <child link="trunk_imu_sensing_point_y"/>
  </joint>
  <!-- Fake joint connecting the mount point of the IMU to
                the sensing point for the x-axis -->
  <joint name="trunk_imu_sensing_point_z_joint" type="fixed">
    <origin rpy="0 0 0" xyz="-0.0256 -0.0006 0.0443"/>
    <parent link="trunk_imu_mount"/>
    <child link="trunk_imu_sensing_point_z"/>
  </joint>
  <!-- Fake link expressing the average sensing reference frame -->
  <link name="trunk_imu">
    <inertial>
      <mass value="0.000"/>
      <origin rpy="0 0 0" xyz="0 0 0"/>
      <inertia ixx="0.00" ixy="0.0" ixz="0.0" iyy="0.00" iyz="0.0" izz="0.00"/>
    </inertial>
    <visual>
      <!-- fake visual to let URDF parser happy -->
      <geometry>
        <sphere radius="0.0005"/>
      </geometry>
    </visual>
  </link>
  <!-- Fake link exactly located at the sensing point for the x-axis -->
  <link name="trunk_imu_sensing_point_x">
    <inertial>
      <mass value="0.000"/>
      <origin rpy="0 0 0" xyz="0 0 0"/>
      <inertia ixx="0.00" ixy="0.0" ixz="0.0" iyy="0.00" iyz="0.0" izz="0.00"/>
    </inertial>
    <visual>
      <!-- fake visual to let URDF parser happy -->
      <geometry>
        <sphere radius="0.0005"/>
      </geometry>
    </visual>
  </link>
  <!-- Fake link expressing the exact sensing point for the y-axis -->
  <link name="trunk_imu_sensing_point_y">
    <inertial>
      <mass value="0.000"/>
      <origin rpy="0 0 0" xyz="0 0 0"/>
      <inertia ixx="0.00" ixy="0.0" ixz="0.0" iyy="0.00" iyz="0.0" izz="0.00"/>
    </inertial>
    <visual>
      <!-- fake visual to let URDF parser happy -->
      <geometry>
        <sphere radius="0.0005"/>
      </geometry>
    </visual>
  </link>
  <!-- Fake link expressing the exact sensing point for the z-axis -->
  <link name="trunk_imu_sensing_point_z">
    <inertial>
      <mass value="0.000"/>
      <origin rpy="0 0 0" xyz="0 0 0"/>
      <inertia ixx="0.00" ixy="0.0" ixz="0.0" iyy="0.00" iyz="0.0" izz="0.00"/>
    </inertial>
    <visual>
      <!-- fake visual to let URDF parser happy -->
      <geometry>
        <sphere radius="0.0005"/>
      </geometry>
    </visual>
  </link>
  <!-- Link -->
  <link name="trunk_imu_mount">
    <inertial>
      <!-- CoM from technical document, rotated by pi/4 -->
      <origin xyz="-0.001697056  -0.001414214  0.0328"/>
      <mass value="0.69"/>
      <!-- izz = 0.5 * 0.69 * (88.9 / 2 / 1000)^2 -->
      <!-- ixx = iyy = 1/12*0.69*(3*(88.9/2000)^2+(73.7/1000)^2) -->
      <inertia ixx="0.000653148" ixy="0.0" ixz="0.0" iyy="0.000653148" iyz="0.0" izz="0.000681652"/>
    </inertial>
    <visual>
      <origin rpy="0 0 0" xyz="0.0 0.0 0.0"/>
      <material name="aluminium">
        <color rgba="0.35 0.35 0.35 1"/>
      </material>
    </visual>
  </link>
  <gazebo>
    <plugin filename="libgazebo_ros_imu.so" name="trunk_imu_controller">
      <alwaysOn>true</alwaysOn>
      <updateRate>250</updateRate>
      <bodyName>trunk_imu</bodyName>
      <topicName>trunk_imu/data</topicName>
      <gaussianNoise>4e-08</gaussianNoise>
      <xyzOffset>0 0 0</xyzOffset>
      <rpyOffset>0 0 0</rpyOffset>
      <serviceName>/trunk_imu</serviceName>
      <frameName>trunk_imu</frameName>
    </plugin>
  </gazebo>
  <!-- Imu definition required for DLS hardware interface of ros control -->
  <gazebo reference="trunk_imu">
    <sensor name="trunk_imu" type="imu">
      <always_on>1</always_on>
      <update_rate>250</update_rate>
      <imu>
        <noise>
          <type>gaussian</type>
          <rate>
            <mean>0</mean>
            <stddev>0.0002</stddev>
            <bias_mean>0.00087</bias_mean>
            <bias_stddev>8e-07</bias_stddev>
          </rate>
          <accel>
            <mean>0</mean>
            <stddev>0.017</stddev>
            <bias_mean>0.002</bias_mean>
            <bias_stddev>0.001</bias_stddev>
          </accel>
        </noise>
      </imu>
    </sensor>
  </gazebo>
  <!-- camera body, with origin at bottom screw mount -->
  <joint name="realsense/front/trunkcamera_joint" type="fixed">
    <origin rpy="-0.005878588 0.7692766 -0.01176524" xyz="0.6958928 0.01937854 -0.0968919"/>
    <parent link="trunk"/>
    <child link="realsense/front/camera_bottom_screw_frame"/>
  </joint>
  <link name="realsense/front/camera_bottom_screw_frame"/>
  <joint name="realsense/front/camera_link_joint" type="fixed">
    <origin rpy="0 0 0" xyz="0 0.0175 0.0125"/>
    <parent link="realsense/front/camera_bottom_screw_frame"/>
    <child link="realsense/front/camera_link"/>
  </joint>
  <link name="realsense/front/camera_link">
    <visual>
      <origin rpy="1.57079632679 0 1.57079632679" xyz="0.0149 -0.0175 0"/>
      <material name="aluminum"/>
    </visual>
    <collision>
      <!--origin xyz="0.0 0.0 ${r430_cam_height/2}" rpy="0 0 0"/-->
      <origin rpy="0 0 0" xyz="0 -0.0175 0"/>
      <geometry>
        <box size="0.02505 0.09 0.025"/>
      </geometry>
    </collision>
    <!-- The following are not reliable values, and should not be used for modeling -->
    <inertial>
      <mass value="0.564"/>
      <origin xyz="0 0 0"/>
      <inertia ixx="0.003881243" ixy="0.0" ixz="0.0" iyy="0.000498940" iyz="0.0" izz="0.003879257"/>
    </inertial>
  </link>
  <!-- camera depth joints and links -->
  <joint name="realsense/front/camera_depth_joint" type="fixed">
    <origin rpy="0 0 0" xyz="0 0 0"/>
    <parent link="realsense/front/camera_link"/>
    <child link="realsense/front/camera_depth_frame"/>
  </joint>
  <link name="realsense/front/camera_depth_frame"/>
  <joint name="realsense/front/camera_depth_optical_joint" type="fixed">
    <origin rpy="-1.57079632679 0 -1.57079632679" xyz="0 0 0"/>
    <parent link="realsense/front/camera_depth_frame"/>
    <child link="realsense/front/camera_depth_optical_frame"/>
  </joint>
  <link name="realsense/front/camera_depth_optical_frame"/>
  <!-- camera left IR joints and links -->
  <joint name="realsense/front/camera_left_ir_joint" type="fixed">
    <origin rpy="0 0 0" xyz="0 0.0 0"/>
    <parent link="realsense/front/camera_depth_frame"/>
    <child link="realsense/front/camera_left_ir_frame"/>
  </joint>
  <link name="realsense/front/camera_left_ir_frame"/>
  <joint name="realsense/front/camera_left_ir_optical_joint" type="fixed">
    <origin rpy="-1.57079632679 0 -1.57079632679" xyz="0 0 0"/>
    <parent link="realsense/front/camera_left_ir_frame"/>
    <child link="realsense/front/camera_left_ir_optical_frame"/>
  </joint>
  <link name="realsense/front/camera_left_ir_optical_frame"/>
  <!-- camera right IR joints and links -->
  <joint name="realsense/front/camera_right_ir_joint" type="fixed">
    <origin rpy="0 0 0" xyz="0 -0.05 0"/>
    <parent link="realsense/front/camera_depth_frame"/>
    <child link="realsense/front/camera_right_ir_frame"/>
  </joint>
  <link name="realsense/front/camera_right_ir_frame"/>
  <joint name="realsense/front/camera_right_ir_optical_joint" type="fixed">
    <origin rpy="-1.57079632679 0 -1.57079632679" xyz="0 0 0"/>
    <parent link="realsense/front/camera_right_ir_frame"/>
    <child link="realsense/front/camera_right_ir_optical_frame"/>
  </joint>
  <link name="realsense/front/camera_right_ir_optical_frame"/>
  <!-- camera color joints and links -->
  <joint name="realsense/front/camera_color_joint" type="fixed">
    <origin rpy="0 0 0" xyz="0 0.015 0"/>
    <parent link="realsense/front/camera_depth_frame"/>
    <child link="realsense/front/camera_color_frame"/>
  </joint>
  <link name="realsense/front/camera_color_frame"/>
  <joint name="realsense/front/camera_color_optical_joint" type="fixed">
    <origin rpy="-1.57079632679 0 -1.57079632679" xyz="0 0 0"/>
    <parent link="realsense/front/camera_color_frame"/>
    <child link="realsense/front/camera_color_optical_frame"/>
  </joint>
  <link name="realsense/front/camera_color_optical_frame"/>
  <gazebo reference="realsense/front/camera_depth_frame">
    <sensor name="realsense/front/camera_depth_frame_depth_sensor" type="depth">
      <always_on>true</always_on>
      <update_rate>30.0</update_rate>
      <camera name="__default__">
        <horizontal_fov>1.047</horizontal_fov>
        <image>
          <format>R8G8B8</format>
          <width>640</width>
          <height>480</height>
        </image>
        <clip>
          <near>0.1</near>
          <far>100</far>
        </clip>
      </camera>
      <plugin filename="libgazebo_ros_openni_kinect.so" name="realsense/front/camera_depth_frame_controller">
        <baseline>0.2</baseline>
        <alwaysOn>true</alwaysOn>
        <updateRate>0</updateRate>
        <cameraName>/realsense/front/camera</cameraName>
        <imageTopicName>/realsense/front/camera/rgb/image_raw</imageTopicName>
        <cameraInfoTopicName>/realsense/front/camera/rgb/camera_info</cameraInfoTopicName>
        <depthImageTopicName>/realsense/front/camera/depth/image_raw</depthImageTopicName>
        <depthImageCameraInfoTopicName>/realsense/front/camera/depth/camera_info</depthImageCameraInfoTopicName>
        <pointCloudTopicName>/realsense/front/camera/depth/points</pointCloudTopicName>
        <frameName>realsense/front/camera_depth_optical_frame</frameName>
        <pointCloudCutoff>0.1</pointCloudCutoff>
        <distortionK1>0.00000001</distortionK1>
        <distortionK2>0.00000001</distortionK2>
        <distortionK3>0.00000001</distortionK3>
        <distortionT1>0.00000001</distortionT1>
        <distortionT2>0.00000001</distortionT2>
        <CxPrime>0</CxPrime>
        <Cx>0</Cx>
        <Cy>0</Cy>
        <focalLength>0</focalLength>
        <hackBaseline>0</hackBaseline>
      </plugin>
    </sensor>
    <material value="Gazebo/Red"/>
  </gazebo>
  <!-- camera body, with origin at bottom screw mount -->
  <joint name="realsense/back/trunkcamera_joint" type="fixed">
    <origin rpy="0 0.785398163398 3.14159" xyz="-0.499873 -0.0000425 -0.109535"/>
    <parent link="trunk"/>
    <child link="realsense/back/camera_bottom_screw_frame"/>
  </joint>
  <link name="realsense/back/camera_bottom_screw_frame"/>
  <joint name="realsense/back/camera_link_joint" type="fixed">
    <origin rpy="0 0 0" xyz="0 0.0175 0.0125"/>
    <parent link="realsense/back/camera_bottom_screw_frame"/>
    <child link="realsense/back/camera_link"/>
  </joint>
  <link name="realsense/back/camera_link">
    <visual>
      <origin rpy="1.57079632679 0 1.57079632679" xyz="0.0149 -0.0175 0"/>
      <material name="aluminum"/>
    </visual>
    <collision>
      <!--origin xyz="0.0 0.0 ${r430_cam_height/2}" rpy="0 0 0"/-->
      <origin rpy="0 0 0" xyz="0 -0.0175 0"/>
      <geometry>
        <box size="0.02505 0.09 0.025"/>
      </geometry>
    </collision>
    <!-- The following are not reliable values, and should not be used for modeling -->
    <inertial>
      <mass value="0.564"/>
      <origin xyz="0 0 0"/>
      <inertia ixx="0.003881243" ixy="0.0" ixz="0.0" iyy="0.000498940" iyz="0.0" izz="0.003879257"/>
    </inertial>
  </link>
  <!-- camera depth joints and links -->
  <joint name="realsense/back/camera_depth_joint" type="fixed">
    <origin rpy="0 0 0" xyz="0 0 0"/>
    <parent link="realsense/back/camera_link"/>
    <child link="realsense/back/camera_depth_frame"/>
  </joint>
  <link name="realsense/back/camera_depth_frame"/>
  <joint name="realsense/back/camera_depth_optical_joint" type="fixed">
    <origin rpy="-1.57079632679 0 -1.57079632679" xyz="0 0 0"/>
    <parent link="realsense/back/camera_depth_frame"/>
    <child link="realsense/back/camera_depth_optical_frame"/>
  </joint>
  <link name="realsense/back/camera_depth_optical_frame"/>
  <!-- camera left IR joints and links -->
  <joint name="realsense/back/camera_left_ir_joint" type="fixed">
    <origin rpy="0 0 0" xyz="0 0.0 0"/>
    <parent link="realsense/back/camera_depth_frame"/>
    <child link="realsense/back/camera_left_ir_frame"/>
  </joint>
  <link name="realsense/back/camera_left_ir_frame"/>
  <joint name="realsense/back/camera_left_ir_optical_joint" type="fixed">
    <origin rpy="-1.57079632679 0 -1.57079632679" xyz="0 0 0"/>
    <parent link="realsense/back/camera_left_ir_frame"/>
    <child link="realsense/back/camera_left_ir_optical_frame"/>
  </joint>
  <link name="realsense/back/camera_left_ir_optical_frame"/>
  <!-- camera right IR joints and links -->
  <joint name="realsense/back/camera_right_ir_joint" type="fixed">
    <origin rpy="0 0 0" xyz="0 -0.05 0"/>
    <parent link="realsense/back/camera_depth_frame"/>
    <child link="realsense/back/camera_right_ir_frame"/>
  </joint>
  <link name="realsense/back/camera_right_ir_frame"/>
  <joint name="realsense/back/camera_right_ir_optical_joint" type="fixed">
    <origin rpy="-1.57079632679 0 -1.57079632679" xyz="0 0 0"/>
    <parent link="realsense/back/camera_right_ir_frame"/>
    <child link="realsense/back/camera_right_ir_optical_frame"/>
  </joint>
  <link name="realsense/back/camera_right_ir_optical_frame"/>
  <!-- camera color joints and links -->
  <joint name="realsense/back/camera_color_joint" type="fixed">
    <origin rpy="0 0 0" xyz="0 0.015 0"/>
    <parent link="realsense/back/camera_depth_frame"/>
    <child link="realsense/back/camera_color_frame"/>
  </joint>
  <link name="realsense/back/camera_color_frame"/>
  <joint name="realsense/back/camera_color_optical_joint" type="fixed">
    <origin rpy="-1.57079632679 0 -1.57079632679" xyz="0 0 0"/>
    <parent link="realsense/back/camera_color_frame"/>
    <child link="realsense/back/camera_color_optical_frame"/>
  </joint>
  <link name="realsense/back/camera_color_optical_frame"/>
  <gazebo reference="realsense/back/camera_depth_frame">
    <sensor name="realsense/back/camera_depth_frame_depth_sensor" type="depth">
      <always_on>true</always_on>
      <update_rate>30.0</update_rate>
      <camera name="__default__">
        <horizontal_fov>1.047</horizontal_fov>
        <image>
          <format>R8G8B8</format>
          <width>640</width>
          <height>480</height>
        </image>
        <clip>
          <near>0.1</near>
          <far>100</far>
        </clip>
      </camera>
      <plugin filename="libgazebo_ros_openni_kinect.so" name="realsense/back/camera_depth_frame_controller">
        <baseline>0.2</baseline>
        <alwaysOn>true</alwaysOn>
        <updateRate>0</updateRate>
        <cameraName>/realsense/back/camera</cameraName>
        <imageTopicName>/realsense/back/camera/rgb/image_raw</imageTopicName>
        <cameraInfoTopicName>/realsense/back/camera/rgb/camera_info</cameraInfoTopicName>
        <depthImageTopicName>/realsense/back/camera/depth/image_raw</depthImageTopicName>
        <depthImageCameraInfoTopicName>/realsense/back/camera/depth/camera_info</depthImageCameraInfoTopicName>
        <pointCloudTopicName>/realsense/back/camera/depth/points</pointCloudTopicName>
        <frameName>realsense/back/camera_depth_optical_frame</frameName>
        <pointCloudCutoff>0.1</pointCloudCutoff>
        <distortionK1>0.00000001</distortionK1>
        <distortionK2>0.00000001</distortionK2>
        <distortionK3>0.00000001</distortionK3>
        <distortionT1>0.00000001</distortionT1>
        <distortionT2>0.00000001</distortionT2>
        <CxPrime>0</CxPrime>
        <Cx>0</Cx>
        <Cy>0</Cy>
        <focalLength>0</focalLength>
        <hackBaseline>0</hackBaseline>
      </plugin>
    </sensor>
    <material value="Gazebo/Red"/>
  </gazebo>
  <!--xacro:VLP-16 parent="trunk">
		<origin xyz="-0.349709 0.0 0.277910" rpy="0 ${-15*PI/180} 0"/> 
	    </xacro:VLP-16-->
  <!--xacro:new_calibration_plate_xacro parent="lf_lowerleg"-->
  <!--origin xyz="0.393 -0.023 -0.1" rpy="${PI/2} 0 0"/-->
  <!--origin xyz="0.3588117 -0.0304911 -0.2088889" rpy="${PI/2} 0 -0.137881"/>
  </xacro:new_calibration_plate_xacro-->
</robot>
